Workbook

Sheet 说明
A1: 页签名称 | B1: 数量 | C1: 说明
A2: JV and CTP清单 | B2: 850 | C2: TA的一级JV and CTP组织
A3: 公司清单 | B3: 2300 | C3: TA的全量组织
A4: 各板块数据 | B4: 1341 | C4: 各板块提交的组织清单

Sheet JV and CTP清单
A1: Entity List | H1: TMS映射 | L1: 关系-分部架构 | N1: 关系-地区架构 | P1: 关系-数据源架构
A2: 人为顺序编码 | E2: 自定义属性 | F2: 自定义属性 | G2: 自定义属性
A3: Code | B3: English Description | C3: 中文 description | D3: Currency | E3: Com Sec Code 1083 | F3: Com Sec Code 0003 | G3: Frango Code | H3: JV映射数量 | I3: JV映射关系 | J3: CTP映射数量 | K3: CTP映射关系 | L3: Node | M3: Node - Description | N3: Node | O3: Node - Description | P3: Node | Q3: Node - Description
A4: 00001 | B4: The Hong Kong and China Gas Company Limited | C4: 香港中华煤气有限公司 | D4: HKD | G4: HKCG | H4: =COUNTIF(JV映射!$C:$C,$A4) -> 0 | I4: {=_xlfn.IFNA(INDEX(JV映射!$A:$A,MATCH($A4,JV映射!$C:$C,0)),"")} | J4: =COUNTIF(CTP映射!$C:$C,$A4) -> 1 | K4: {=_xlfn.IFNA(INDEX(CTP映射!A:A,MATCH($A4,CTP映射!C:C,0)),"")} -> JYGLF0668 | L4: =VLOOKUP($A4,JV分部架构!$A:$F,5,0) -> ORG|HK_CORE | M4: =VLOOKUP($A4,JV分部架构!$A:$F,6,0) -> Hong Kong Business | N4: =VLOOKUP($A4,JV地区架构!$A:$F,5,0) -> LOC|HK | O4: =VLOOKUP($A4,JV地区架构!$A:$F,6,0) -> Hong Kong | P4: =VLOOKUP($A4,JV数据源架构!$A:$F,5,0) -> SRC|HK_SAP | Q4: =VLOOKUP($A4,JV数据源架构!$A:$F,6,0) -> SAP直接上报TA
A5: 00002 | B5: Skyward Investments Limited | C5: Skyward Investments Limited | D5: HKD | G5: SKYW | H5: =COUNTIF(JV映射!$C:$C,$A5) -> 0 | I5: {=_xlfn.IFNA(INDEX(JV映射!$A:$A,MATCH($A5,JV映射!$C:$C,0)),"")} | J5: =COUNTIF(CTP映射!$C:$C,$A5) -> 0 | K5: {=_xlfn.IFNA(INDEX(CTP映射!A:A,MATCH($A5,CTP映射!C:C,0)),"")} | L5: =VLOOKUP($A5,JV分部架构!$A:$F,5,0) -> ORG|HK_BUSINESS | M5: =VLOOKUP($A5,JV分部架构!$A:$F,6,0) -> HK Business | N5: =VLOOKUP($A5,JV地区架构!$A:$F,5,0) -> LOC|HK | O5: =VLOOKUP($A5,JV地区架构!$A:$F,6,0) -> Hong Kong | P5: =VLOOKUP($A5,JV数据源架构!$A:$F,5,0) -> SRC|HK_SAP | Q5: =VLOOKUP($A5,JV数据源架构!$A:$F,6,0) -> SAP直接上报TA
A6: 00003 | B6: Brilliant World International Limited | C6: Brilliant World International Limited | D6: HKD | G6: BRIL | H6: =COUNTIF(JV映射!$C:$C,$A6) -> 0 | I6: {=_xlfn.IFNA(INDEX(JV映射!$A:$A,MATCH($A6,JV映射!$C:$C,0)),"")} | J6: =COUNTIF(CTP映射!$C:$C,$A6) -> 0 | K6: {=_xlfn.IFNA(INDEX(CTP映射!A:A,MATCH($A6,CTP映射!C:C,0)),"")} | L6: =VLOOKUP($A6,JV分部架构!$A:$F,5,0) -> ORG|HK_BUSINESS | M6: =VLOOKUP($A6,JV分部架构!$A:$F,6,0) -> HK Business | N6: =VLOOKUP($A6,JV地区架构!$A:$F,5,0) -> LOC|BVI | O6: =VLOOKUP($A6,JV地区架构!$A:$F,6,0) -> BVI | P6: =VLOOKUP($A6,JV数据源架构!$A:$F,5,0) -> SRC|HK_SAP | Q6: =VLOOKUP($A6,JV数据源架构!$A:$F,6,0) -> SAP直接上报TA
A7: 00004 | B7: Edonlite Holdings Limited | C7: Edonlite Holdings Limited | D7: HKD | G7: EDON | H7: =COUNTIF(JV映射!$C:$C,$A7) -> 0 | I7: {=_xlfn.IFNA(INDEX(JV映射!$A:$A,MATCH($A7,JV映射!$C:$C,0)),"")} | J7: =COUNTIF(CTP映射!$C:$C,$A7) -> 0 | K7: {=_xlfn.IFNA(INDEX(CTP映射!A:A,MATCH($A7,CTP映射!C:C,0)),"")} | L7: =VLOOKUP($A7,JV分部架构!$A:$F,5,0) -> ORG|HK_BUSINESS | M7: =VLOOKUP($A7,JV分部架构!$A:$F,6,0) -> HK Business | N7: =VLOOKUP($A7,JV地区架构!$A:$F,5,0) -> LOC|BVI | O7: =VLOOKUP($A7,JV地区架构!$A:$F,6,0) -> BVI | P7: =VLOOKUP($A7,JV数据源架构!$A:$F,5,0) -> SRC|HK_SAP | Q7: =VLOOKUP($A7,JV数据源架构!$A:$F,6,0) -> SAP直接上报TA
A8: 00005 | B8: Primebay Investments Limited | C8: Primebay Investments Limited | D8: HKD | G8: PRIM | H8: =COUNTIF(JV映射!$C:$C,$A8) -> 0 | I8: {=_xlfn.IFNA(INDEX(JV映射!$A:$A,MATCH($A8,JV映射!$C:$C,0)),"")} | J8: =COUNTIF(CTP映射!$C:$C,$A8) -> 0 | K8: {=_xlfn.IFNA(INDEX(CTP映射!A:A,MATCH($A8,CTP映射!C:C,0)),"")} | L8: =VLOOKUP($A8,JV分部架构!$A:$F,5,0) -> ORG|HK_BUSINESS | M8: =VLOOKUP($A8,JV分部架构!$A:$F,6,0) -> HK Business | N8: =VLOOKUP($A8,JV地区架构!$A:$F,5,0) -> LOC|BVI | O8: =VLOOKUP($A8,JV地区架构!$A:$F,6,0) -> BVI | P8: =VLOOKUP($A8,JV数据源架构!$A:$F,5,0) -> SRC|HK_SAP | Q8: =VLOOKUP($A8,JV数据源架构!$A:$F,6,0) -> SAP直接上报TA
A9: 00006 | B9: China Guide Resources Limited | C9: 中诚资源有限公司 | D9: HKD | G9: GUID | H9: =COUNTIF(JV映射!$C:$C,$A9) -> 0 | I9: {=_xlfn.IFNA(INDEX(JV映射!$A:$A,MATCH($A9,JV映射!$C:$C,0)),"")} | J9: =COUNTIF(CTP映射!$C:$C,$A9) -> 1 | K9: {=_xlfn.IFNA(INDEX(CTP映射!A:A,MATCH($A9,CTP映射!C:C,0)),"")} -> JYGLF0716 | L9: =VLOOKUP($A9,JV分部架构!$A:$F,5,0) -> ORG|HK_BUSINESS | M9: =VLOOKUP($A9,JV分部架构!$A:$F,6,0) -> HK Business | N9: =VLOOKUP($A9,JV地区架构!$A:$F,5,0) -> LOC|HK | O9: =VLOOKUP($A9,JV地区架构!$A:$F,6,0) -> Hong Kong | P9: =VLOOKUP($A9,JV数据源架构!$A:$F,5,0) -> SRC|HK_SAP | Q9: =VLOOKUP($A9,JV数据源架构!$A:$F,6,0) -> SAP直接上报TA
A10: 00007 | B10: Smoothing Investment Limited | C10: 伟诚倡投资有限公司 | D10: HKD | G10: SMOO | H10: =COUNTIF(JV映射!$C:$C,$A10) -> 0 | I10: {=_xlfn.IFNA(INDEX(JV映射!$A:$A,MATCH($A10,JV映射!$C:$C,0)),"")} | J10: =COUNTIF(CTP映射!$C:$C,$A10) -> 0 | K10: {=_xlfn.IFNA(INDEX(CTP映射!A:A,MATCH($A10,CTP映射!C:C,0)),"")} | L10: =VLOOKUP($A10,JV分部架构!$A:$F,5,0) -> ORG|HK_BUSINESS | M10: =VLOOKUP($A10,JV分部架构!$A:$F,6,0) -> HK Business | N10: =VLOOKUP($A10,JV地区架构!$A:$F,5,0) -> LOC|HK | O10: =VLOOKUP($A10,JV地区架构!$A:$F,6,0) -> Hong Kong | P10: =VLOOKUP($A10,JV数据源架构!$A:$F,5,0) -> SRC|HK_SAP | Q10: =VLOOKUP($A10,JV数据源架构!$A:$F,6,0) -> SAP直接上报TA
A11: 00008 | B11: Quality Testing Services Limited | C11: 质量测检服务有限公司 | D11: HKD | G11: QUALR | H11: =COUNTIF(JV映射!$C:$C,$A11) -> 0 | I11: {=_xlfn.IFNA(INDEX(JV映射!$A:$A,MATCH($A11,JV映射!$C:$C,0)),"")} | J11: =COUNTIF(CTP映射!$C:$C,$A11) -> 1 | K11: {=_xlfn.IFNA(INDEX(CTP映射!A:A,MATCH($A11,CTP映射!C:C,0)),"")} -> JYGLF0699 | L11: =VLOOKUP($A11,JV分部架构!$A:$F,5,0) -> ORG|HK_BUSINESS | M11: =VLOOKUP($A11,JV分部架构!$A:$F,6,0) -> HK Business | N11: =VLOOKUP($A11,JV地区架构!$A:$F,5,0) -> LOC|HK | O11: =VLOOKUP($A11,JV地区架构!$A:$F,6,0) -> Hong Kong | P11: =VLOOKUP($A11,JV数据源架构!$A:$F,5,0) -> SRC|HK_SAP | Q11: =VLOOKUP($A11,JV数据源架构!$A:$F,6,0) -> SAP直接上报TA
A12: 00009 | B12: P-Tech Engineering Company Limited | C12: 卓诚工程有限公司 | D12: HKD | G12: TING | H12: =COUNTIF(JV映射!$C:$C,$A12) -> 0 | I12: {=_xlfn.IFNA(INDEX(JV映射!$A:$A,MATCH($A12,JV映射!$C:$C,0)),"")} | J12: =COUNTIF(CTP映射!$C:$C,$A12) -> 1 | K12: {=_xlfn.IFNA(INDEX(CTP映射!A:A,MATCH($A12,CTP映射!C:C,0)),"")} -> JYGLF0402 | L12: =VLOOKUP($A12,JV分部架构!$A:$F,5,0) -> ORG|P_TECH | M12: =VLOOKUP($A12,JV分部架构!$A:$F,6,0) -> P-Tech | N12: =VLOOKUP($A12,JV地区架构!$A:$F,5,0) -> LOC|HK | O12: =VLOOKUP($A12,JV地区架构!$A:$F,6,0) -> Hong Kong | P12: =VLOOKUP($A12,JV数据源架构!$A:$F,5,0) -> SRC|HK_SAP | Q12: =VLOOKUP($A12,JV数据源架构!$A:$F,6,0) -> SAP直接上报TA
A13: 00010 | B13: China Gas Company Limited | C13: 中华煤气有限公司 | D13: HKD | G13: CGAS | H13: =COUNTIF(JV映射!$C:$C,$A13) -> 0 | I13: {=_xlfn.IFNA(INDEX(JV映射!$A:$A,MATCH($A13,JV映射!$C:$C,0)),"")} | J13: =COUNTIF(CTP映射!$C:$C,$A13) -> 0 | K13: {=_xlfn.IFNA(INDEX(CTP映射!A:A,MATCH($A13,CTP映射!C:C,0)),"")} | L13: =VLOOKUP($A13,JV分部架构!$A:$F,5,0) -> ORG|HK_BUSINESS | M13: =VLOOKUP($A13,JV分部架构!$A:$F,6,0) -> HK Business | N13: =VLOOKUP($A13,JV地区架构!$A:$F,5,0) -> LOC|HK | O13: =VLOOKUP($A13,JV地区架构!$A:$F,6,0) -> Hong Kong | P13: =VLOOKUP($A13,JV数据源架构!$A:$F,5,0) -> SRC|HK_SAP | Q13: =VLOOKUP($A13,JV数据源架构!$A:$F,6,0) -> SAP直接上报TA
A14: 00011 | B14: Hong Kong Gas Company Limited | C14: 香港煤气有限公司 | D14: HKD | G14: HGAS | H14: =COUNTIF(JV映射!$C:$C,$A14) -> 0 | I14: {=_xlfn.IFNA(INDEX(JV映射!$A:$A,MATCH($A14,JV映射!$C:$C,0)),"")} | J14: =COUNTIF(CTP映射!$C:$C,$A14) -> 0 | K14: {=_xlfn.IFNA(INDEX(CTP映射!A:A,MATCH($A14,CTP映射!C:C,0)),"")} | L14: =VLOOKUP($A14,JV分部架构!$A:$F,5,0) -> ORG|HK_BUSINESS | M14: =VLOOKUP($A14,JV分部架构!$A:$F,6,0) -> HK Business | N14: =VLOOKUP($A14,JV地区架构!$A:$F,5,0) -> LOC|HK | O14: =VLOOKUP($A14,JV地区架构!$A:$F,6,0) -> Hong Kong | P14: =VLOOKUP($A14,JV数据源架构!$A:$F,5,0) -> SRC|HK_SAP | Q14: =VLOOKUP($A14,JV数据源架构!$A:$F,6,0) -> SAP直接上报TA
A15: 00012 | B15: Alpha Idea International Limited | C15: 星满国际有限公司 | D15: HKD | G15: AIIL | H15: =COUNTIF(JV映射!$C:$C,$A15) -> 0 | I15: {=_xlfn.IFNA(INDEX(JV映射!$A:$A,MATCH($A15,JV映射!$C:$C,0)),"")} | J15: =COUNTIF(CTP映射!$C:$C,$A15) -> 0 | K15: {=_xlfn.IFNA(INDEX(CTP映射!A:A,MATCH($A15,CTP映射!C:C,0)),"")} | L15: =VLOOKUP($A15,JV分部架构!$A:$F,5,0) -> ORG|EB_HK | M15: =VLOOKUP($A15,JV分部架构!$A:$F,6,0) -> Extended Business - Hong Kong | N15: =VLOOKUP($A15,JV地区架构!$A:$F,5,0) -> LOC|HK | O15: =VLOOKUP($A15,JV地区架构!$A:$F,6,0) -> Hong Kong | P15: =VLOOKUP($A15,JV数据源架构!$A:$F,5,0) -> SRC|HK_SAP | Q15: =VLOOKUP($A15,JV数据源架构!$A:$F,6,0) -> SAP直接上报TA
... A613: 00863 | B613: 威海港能投清洁能源有限公司 | C613: 威海港能投清洁能源有限公司 | D613: CNY | G613: SDWHPCE | H613: =COUNTIF(JV映射!$C:$C,$A613) -> 1 | I613: {=_xlfn.IFNA(INDEX(JV映射!$A:$A,MATCH($A613,JV映射!$C:$C,0)),"")} -> 384 | J613: =COUNTIF(CTP映射!$C:$C,$A613) -> 1 | K613: {=_xlfn.IFNA(INDEX(CTP映射!A:A,MATCH($A613,CTP映射!C:C,0)),"")} -> 384 | L613: =VLOOKUP($A613,JV分部架构!$A:$F,5,0) -> ORG|MU_RENEWABLE_ENERGY_TSEL | M613: =VLOOKUP($A613,JV分部架构!$A:$F,6,0) -> Renewable Energy (TSEL) | N613: =VLOOKUP($A613,JV地区架构!$A:$F,5,0) -> LOC|MLC_37 | O613: =VLOOKUP($A613,JV地区架构!$A:$F,6,0) -> Shandong | P613: =VLOOKUP($A613,JV数据源架构!$A:$F,5,0) -> SRC|DW_TMS | Q613: =VLOOKUP($A613,JV数据源架构!$A:$F,6,0) -> 通过DW上报TA（TMS）
A614: 00864 | B614: 滁州港华综合能源有限公司（合并） | C614: 滁州港华综合能源有限公司（合并） | D614: CNY | H614: =COUNTIF(JV映射!$C:$C,$A614) -> 1 | I614: {=_xlfn.IFNA(INDEX(JV映射!$A:$A,MATCH($A614,JV映射!$C:$C,0)),"")} -> AHCZNE | J614: =COUNTIF(CTP映射!$C:$C,$A614) -> 1 | K614: {=_xlfn.IFNA(INDEX(CTP映射!A:A,MATCH($A614,CTP映射!C:C,0)),"")} -> 381 | L614: =VLOOKUP($A614,JV分部架构!$A:$F,5,0) -> ORG|MU_RENEWABLE_ENERGY_TSEL | M614: =VLOOKUP($A614,JV分部架构!$A:$F,6,0) -> Renewable Energy (TSEL) | N614: =VLOOKUP($A614,JV地区架构!$A:$F,5,0) -> LOC|MLC_34 | O614: =VLOOKUP($A614,JV地区架构!$A:$F,6,0) -> Anhui | P614: =VLOOKUP($A614,JV数据源架构!$A:$F,5,0) -> SRC|DW_TMS | Q614: =VLOOKUP($A614,JV数据源架构!$A:$F,6,0) -> 通过DW上报TA（TMS）
A615: 00865 | B615: 海口港华智慧能源有限公司 | C615: 海口港华智慧能源有限公司 | D615: CNY | G615: HNHKGCE | H615: =COUNTIF(JV映射!$C:$C,$A615) -> 1 | I615: {=_xlfn.IFNA(INDEX(JV映射!$A:$A,MATCH($A615,JV映射!$C:$C,0)),"")} -> 393 | J615: =COUNTIF(CTP映射!$C:$C,$A615) -> 1 | K615: {=_xlfn.IFNA(INDEX(CTP映射!A:A,MATCH($A615,CTP映射!C:C,0)),"")} -> 393 | L615: =VLOOKUP($A615,JV分部架构!$A:$F,5,0) -> ORG|MU_RENEWABLE_ENERGY_TSEL | M615: =VLOOKUP($A615,JV分部架构!$A:$F,6,0) -> Renewable Energy (TSEL) | N615: =VLOOKUP($A615,JV地区架构!$A:$F,5,0) -> LOC|MLC_46 | O615: =VLOOKUP($A615,JV地区架构!$A:$F,6,0) -> Hainan | P615: =VLOOKUP($A615,JV数据源架构!$A:$F,5,0) -> SRC|DW_TMS | Q615: =VLOOKUP($A615,JV数据源架构!$A:$F,6,0) -> 通过DW上报TA（TMS）
A616: 00867 | B616: 柳州港能投智慧能源有限公司 | C616: 柳州港能投智慧能源有限公司 | D616: CNY | G616: GXLZPE | H616: =COUNTIF(JV映射!$C:$C,$A616) -> 1 | I616: {=_xlfn.IFNA(INDEX(JV映射!$A:$A,MATCH($A616,JV映射!$C:$C,0)),"")} -> 400 | J616: =COUNTIF(CTP映射!$C:$C,$A616) -> 2 | K616: {=_xlfn.IFNA(INDEX(CTP映射!A:A,MATCH($A616,CTP映射!C:C,0)),"")} -> 400 | L616: =VLOOKUP($A616,JV分部架构!$A:$F,5,0) -> ORG|MU_RENEWABLE_ENERGY_TSEL | M616: =VLOOKUP($A616,JV分部架构!$A:$F,6,0) -> Renewable Energy (TSEL) | N616: =VLOOKUP($A616,JV地区架构!$A:$F,5,0) -> LOC|MLC_45 | O616: =VLOOKUP($A616,JV地区架构!$A:$F,6,0) -> Guangxi | P616: =VLOOKUP($A616,JV数据源架构!$A:$F,5,0) -> SRC|DW_TMS | Q616: =VLOOKUP($A616,JV数据源架构!$A:$F,6,0) -> 通过DW上报TA（TMS）
A617: 00868 | B617: Anqiu TowngasChina PV PowerGenerationCo., Ltd. | C617: 安丘航洲新能源科技有限公司 | D617: CNY | G617: PGAQJV | H617: =COUNTIF(JV映射!$C:$C,$A617) -> 1 | I617: {=_xlfn.IFNA(INDEX(JV映射!$A:$A,MATCH($A617,JV映射!$C:$C,0)),"")} -> 216 | J617: =COUNTIF(CTP映射!$C:$C,$A617) -> 1 | K617: {=_xlfn.IFNA(INDEX(CTP映射!A:A,MATCH($A617,CTP映射!C:C,0)),"")} -> 216 | L617: =VLOOKUP($A617,JV分部架构!$A:$F,5,0) -> ORG|MU_RENEWABLE_ENERGY_TSEL | M617: =VLOOKUP($A617,JV分部架构!$A:$F,6,0) -> Renewable Energy (TSEL) | N617: =VLOOKUP($A617,JV地区架构!$A:$F,5,0) -> LOC|MLC_37 | O617: =VLOOKUP($A617,JV地区架构!$A:$F,6,0) -> Shandong | P617: =VLOOKUP($A617,JV数据源架构!$A:$F,5,0) -> SRC|DW_TMS | Q617: =VLOOKUP($A617,JV数据源架构!$A:$F,6,0) -> 通过DW上报TA（TMS）
A618: 00869 | B618: 青岛嘉嘉通新能源科技有限公司 | C618: 青岛嘉嘉通新能源科技有限公司 | D618: CNY | G618: PGQDJV | H618: =COUNTIF(JV映射!$C:$C,$A618) -> 1 | I618: {=_xlfn.IFNA(INDEX(JV映射!$A:$A,MATCH($A618,JV映射!$C:$C,0)),"")} -> 221 | J618: =COUNTIF(CTP映射!$C:$C,$A618) -> 1 | K618: {=_xlfn.IFNA(INDEX(CTP映射!A:A,MATCH($A618,CTP映射!C:C,0)),"")} -> 221 | L618: =VLOOKUP($A618,JV分部架构!$A:$F,5,0) -> ORG|MU_RENEWABLE_ENERGY_TSEL | M618: =VLOOKUP($A618,JV分部架构!$A:$F,6,0) -> Renewable Energy (TSEL) | N618: =VLOOKUP($A618,JV地区架构!$A:$F,5,0) -> LOC|MLC_37 | O618: =VLOOKUP($A618,JV地区架构!$A:$F,6,0) -> Shandong | P618: =VLOOKUP($A618,JV数据源架构!$A:$F,5,0) -> SRC|DW_TMS | Q618: =VLOOKUP($A618,JV数据源架构!$A:$F,6,0) -> 通过DW上报TA（TMS）
A619: 00870 | B619: 滨州鑫润丰新能源有限公司 | C619: 滨州鑫润丰新能源有限公司 | D619: CNY | G619: PGBZJV | H619: =COUNTIF(JV映射!$C:$C,$A619) -> 1 | I619: {=_xlfn.IFNA(INDEX(JV映射!$A:$A,MATCH($A619,JV映射!$C:$C,0)),"")} -> 253 | J619: =COUNTIF(CTP映射!$C:$C,$A619) -> 1 | K619: {=_xlfn.IFNA(INDEX(CTP映射!A:A,MATCH($A619,CTP映射!C:C,0)),"")} -> 253 | L619: =VLOOKUP($A619,JV分部架构!$A:$F,5,0) -> ORG|MU_RENEWABLE_ENERGY_TSEL | M619: =VLOOKUP($A619,JV分部架构!$A:$F,6,0) -> Renewable Energy (TSEL) | N619: =VLOOKUP($A619,JV地区架构!$A:$F,5,0) -> LOC|MLC_37 | O619: =VLOOKUP($A619,JV地区架构!$A:$F,6,0) -> Shandong | P619: =VLOOKUP($A619,JV数据源架构!$A:$F,5,0) -> SRC|DW_TMS | Q619: =VLOOKUP($A619,JV数据源架构!$A:$F,6,0) -> 通过DW上报TA（TMS）
A620: 00871 | B620: 马鞍山市郑蒲港新区港能投光伏有限公司 | C620: 马鞍山市郑蒲港新区港能投光伏有限公司 | D620: CNY | G620: PVZPJV | H620: =COUNTIF(JV映射!$C:$C,$A620) -> 1 | I620: {=_xlfn.IFNA(INDEX(JV映射!$A:$A,MATCH($A620,JV映射!$C:$C,0)),"")} -> 280 | J620: =COUNTIF(CTP映射!$C:$C,$A620) -> 1 | K620: {=_xlfn.IFNA(INDEX(CTP映射!A:A,MATCH($A620,CTP映射!C:C,0)),"")} -> 280 | L620: =VLOOKUP($A620,JV分部架构!$A:$F,5,0) -> ORG|MU_RENEWABLE_ENERGY_TSEL | M620: =VLOOKUP($A620,JV分部架构!$A:$F,6,0) -> Renewable Energy (TSEL) | N620: =VLOOKUP($A620,JV地区架构!$A:$F,5,0) -> LOC|MLC_34 | O620: =VLOOKUP($A620,JV地区架构!$A:$F,6,0) -> Anhui | P620: =VLOOKUP($A620,JV数据源架构!$A:$F,5,0) -> SRC|DW_TMS | Q620: =VLOOKUP($A620,JV数据源架构!$A:$F,6,0) -> 通过DW上报TA（TMS）
A621: 00872 | B621: 本溪港能投智慧能源有限公司 | C621: 本溪港能投智慧能源有限公司 | D621: CNY | G621: LNBXE | H621: =COUNTIF(JV映射!$C:$C,$A621) -> 1 | I621: {=_xlfn.IFNA(INDEX(JV映射!$A:$A,MATCH($A621,JV映射!$C:$C,0)),"")} -> 279 | J621: =COUNTIF(CTP映射!$C:$C,$A621) -> 1 | K621: {=_xlfn.IFNA(INDEX(CTP映射!A:A,MATCH($A621,CTP映射!C:C,0)),"")} -> 279 | L621: =VLOOKUP($A621,JV分部架构!$A:$F,5,0) -> ORG|MU_RENEWABLE_ENERGY_TSEL | M621: =VLOOKUP($A621,JV分部架构!$A:$F,6,0) -> Renewable Energy (TSEL) | N621: =VLOOKUP($A621,JV地区架构!$A:$F,5,0) -> LOC|MLC_21 | O621: =VLOOKUP($A621,JV地区架构!$A:$F,6,0) -> Liaoning | P621: =VLOOKUP($A621,JV数据源架构!$A:$F,5,0) -> SRC|DW_TMS | Q621: =VLOOKUP($A621,JV数据源架构!$A:$F,6,0) -> 通过DW上报TA（TMS）
A622: 00873 | B622: 青岛港能投清洁能源有限公司 | C622: 青岛港能投清洁能源有限公司 | D622: CNY | G622: SDQDLCE | H622: =COUNTIF(JV映射!$C:$C,$A622) -> 1 | I622: {=_xlfn.IFNA(INDEX(JV映射!$A:$A,MATCH($A622,JV映射!$C:$C,0)),"")} -> 370 | J622: =COUNTIF(CTP映射!$C:$C,$A622) -> 1 | K622: {=_xlfn.IFNA(INDEX(CTP映射!A:A,MATCH($A622,CTP映射!C:C,0)),"")} -> 370 | L622: =VLOOKUP($A622,JV分部架构!$A:$F,5,0) -> ORG|MU_RENEWABLE_ENERGY_TSEL | M622: =VLOOKUP($A622,JV分部架构!$A:$F,6,0) -> Renewable Energy (TSEL) | N622: =VLOOKUP($A622,JV地区架构!$A:$F,5,0) -> LOC|MLC_37 | O622: =VLOOKUP($A622,JV地区架构!$A:$F,6,0) -> Shandong | P622: =VLOOKUP($A622,JV数据源架构!$A:$F,5,0) -> SRC|DW_TMS | Q622: =VLOOKUP($A622,JV数据源架构!$A:$F,6,0) -> 通过DW上报TA（TMS）
A623: 00874 | B623: 溧阳恒电新能源科技有限公司 | C623: 溧阳恒电新能源科技有限公司 | D623: CNY | G623: PGLYJV | H623: =COUNTIF(JV映射!$C:$C,$A623) -> 1 | I623: {=_xlfn.IFNA(INDEX(JV映射!$A:$A,MATCH($A623,JV映射!$C:$C,0)),"")} -> 220 | J623: =COUNTIF(CTP映射!$C:$C,$A623) -> 1 | K623: {=_xlfn.IFNA(INDEX(CTP映射!A:A,MATCH($A623,CTP映射!C:C,0)),"")} -> 220 | L623: =VLOOKUP($A623,JV分部架构!$A:$F,5,0) -> ORG|MU_RENEWABLE_ENERGY_TSEL | M623: =VLOOKUP($A623,JV分部架构!$A:$F,6,0) -> Renewable Energy (TSEL) | N623: =VLOOKUP($A623,JV地区架构!$A:$F,5,0) -> LOC|MLC_32 | O623: =VLOOKUP($A623,JV地区架构!$A:$F,6,0) -> Jiangsu | P623: =VLOOKUP($A623,JV数据源架构!$A:$F,5,0) -> SRC|DW_TMS | Q623: =VLOOKUP($A623,JV数据源架构!$A:$F,6,0) -> 通过DW上报TA（TMS）
A624: 00875 | B624: 苏州光辰新能源科技有限公司 | C624: 苏州光辰新能源科技有限公司 | D624: CNY | G624: PGSUJV | H624: =COUNTIF(JV映射!$C:$C,$A624) -> 1 | I624: {=_xlfn.IFNA(INDEX(JV映射!$A:$A,MATCH($A624,JV映射!$C:$C,0)),"")} -> 246 | J624: =COUNTIF(CTP映射!$C:$C,$A624) -> 1 | K624: {=_xlfn.IFNA(INDEX(CTP映射!A:A,MATCH($A624,CTP映射!C:C,0)),"")} -> 246 | L624: =VLOOKUP($A624,JV分部架构!$A:$F,5,0) -> ORG|MU_RENEWABLE_ENERGY_TSEL | M624: =VLOOKUP($A624,JV分部架构!$A:$F,6,0) -> Renewable Energy (TSEL) | N624: =VLOOKUP($A624,JV地区架构!$A:$F,5,0) -> LOC|MLC_32 | O624: =VLOOKUP($A624,JV地区架构!$A:$F,6,0) -> Jiangsu | P624: =VLOOKUP($A624,JV数据源架构!$A:$F,5,0) -> SRC|DW_TMS | Q624: =VLOOKUP($A624,JV数据源架构!$A:$F,6,0) -> 通过DW上报TA（TMS）
A625: 00876 | B625: 郑州市港密新能源有限公司 | C625: 郑州市港密新能源有限公司 | D625: CNY | G625: HNZZGCE | H625: =COUNTIF(JV映射!$C:$C,$A625) -> 1 | I625: {=_xlfn.IFNA(INDEX(JV映射!$A:$A,MATCH($A625,JV映射!$C:$C,0)),"")} -> HNZZGCE | J625: =COUNTIF(CTP映射!$C:$C,$A625) -> 1 | K625: {=_xlfn.IFNA(INDEX(CTP映射!A:A,MATCH($A625,CTP映射!C:C,0)),"")} -> 366 | L625: =VLOOKUP($A625,JV分部架构!$A:$F,5,0) -> ORG|MU_RENEWABLE_ENERGY_TSEL | M625: =VLOOKUP($A625,JV分部架构!$A:$F,6,0) -> Renewable Energy (TSEL) | N625: =VLOOKUP($A625,JV地区架构!$A:$F,5,0) -> LOC|MLC_41 | O625: =VLOOKUP($A625,JV地区架构!$A:$F,6,0) -> Henan | P625: =VLOOKUP($A625,JV数据源架构!$A:$F,5,0) -> SRC|DW_TMS | Q625: =VLOOKUP($A625,JV数据源架构!$A:$F,6,0) -> 通过DW上报TA（TMS）
A626: 00877 | B626: 黄冈港能投智慧能源有限公司 | C626: 黄冈港能投智慧能源有限公司 | D626: CNY | G626: HBHGHCE | H626: =COUNTIF(JV映射!$C:$C,$A626) -> 1 | I626: {=_xlfn.IFNA(INDEX(JV映射!$A:$A,MATCH($A626,JV映射!$C:$C,0)),"")} -> 376 | J626: =COUNTIF(CTP映射!$C:$C,$A626) -> 1 | K626: {=_xlfn.IFNA(INDEX(CTP映射!A:A,MATCH($A626,CTP映射!C:C,0)),"")} -> 376 | L626: =VLOOKUP($A626,JV分部架构!$A:$F,5,0) -> ORG|MU_RENEWABLE_ENERGY_TSEL | M626: =VLOOKUP($A626,JV分部架构!$A:$F,6,0) -> Renewable Energy (TSEL) | N626: =VLOOKUP($A626,JV地区架构!$A:$F,5,0) -> LOC|MLC_42 | O626: =VLOOKUP($A626,JV地区架构!$A:$F,6,0) -> Hubei | P626: =VLOOKUP($A626,JV数据源架构!$A:$F,5,0) -> SRC|DW_TMS | Q626: =VLOOKUP($A626,JV数据源架构!$A:$F,6,0) -> 通过DW上报TA（TMS）
... A718: 01044 | B718: Lezhi Hong Kong and China Gas Company Limited | C718: 乐至港华燃气有限公司 | D718: CNY | G718: SCLZ | H718: =COUNTIF(JV映射!$C:$C,$A718) -> 1 | I718: {=_xlfn.IFNA(INDEX(JV映射!$A:$A,MATCH($A718,JV映射!$C:$C,0)),"")} -> 087 | J718: =COUNTIF(CTP映射!$C:$C,$A718) -> 1 | K718: {=_xlfn.IFNA(INDEX(CTP映射!A:A,MATCH($A718,CTP映射!C:C,0)),"")} -> 087 | L718: =VLOOKUP($A718,JV分部架构!$A:$F,5,0) -> ORG|MU_GAS_TSEL | M718: =VLOOKUP($A718,JV分部架构!$A:$F,6,0) -> City Gas (TSEL) | N718: =VLOOKUP($A718,JV地区架构!$A:$F,5,0) -> LOC|MLC_51 | O718: =VLOOKUP($A718,JV地区架构!$A:$F,6,0) -> Sichuan | P718: =VLOOKUP($A718,JV数据源架构!$A:$F,5,0) -> SRC|DW_TMS | Q718: =VLOOKUP($A718,JV数据源架构!$A:$F,6,0) -> 通过DW上报TA（TMS）
A719: 01045 | B719: 兴义港华舒适家科技服务有限公司 | C719: 兴义港华舒适家科技服务有限公司 | D719: CNY | H719: =COUNTIF(JV映射!$C:$C,$A719) -> 1 | I719: {=_xlfn.IFNA(INDEX(JV映射!$A:$A,MATCH($A719,JV映射!$C:$C,0)),"")} -> 20101 | J719: =COUNTIF(CTP映射!$C:$C,$A719) -> 1 | K719: {=_xlfn.IFNA(INDEX(CTP映射!A:A,MATCH($A719,CTP映射!C:C,0)),"")} -> 20101 | L719: =VLOOKUP($A719,JV分部架构!$A:$F,5,0) -> ORG|EB_PRC | M719: =VLOOKUP($A719,JV分部架构!$A:$F,6,0) -> Extended Business - Mainland | N719: =VLOOKUP($A719,JV地区架构!$A:$F,5,0) -> #N/A | O719: =VLOOKUP($A719,JV地区架构!$A:$F,6,0) -> #N/A | P719: =VLOOKUP($A719,JV数据源架构!$A:$F,5,0) -> SRC|DW_TMS | Q719: =VLOOKUP($A719,JV数据源架构!$A:$F,6,0) -> 通过DW上报TA（TMS）
A720: 01047 | B720: Hong Kong & China Gas (Yingkou) Limited | C720: 香港中华煤气（营口）有限公司 | D720: HKD | G720: HKYK | H720: =COUNTIF(JV映射!$C:$C,$A720) -> 0 | I720: {=_xlfn.IFNA(INDEX(JV映射!$A:$A,MATCH($A720,JV映射!$C:$C,0)),"")} | J720: =COUNTIF(CTP映射!$C:$C,$A720) -> 1 | K720: {=_xlfn.IFNA(INDEX(CTP映射!A:A,MATCH($A720,CTP映射!C:C,0)),"")} -> JYGLF0601 | L720: =VLOOKUP($A720,JV分部架构!$A:$F,5,0) -> ORG|OTHER | M720: =VLOOKUP($A720,JV分部架构!$A:$F,6,0) -> Other Businesses | N720: =VLOOKUP($A720,JV地区架构!$A:$F,5,0) -> LOC|BVI | O720: =VLOOKUP($A720,JV地区架构!$A:$F,6,0) -> BVI | P720: =VLOOKUP($A720,JV数据源架构!$A:$F,5,0) -> SRC|HK_SAP | Q720: =VLOOKUP($A720,JV数据源架构!$A:$F,6,0) -> SAP直接上报TA
A721: 01048 | B721: 港华舒适家（成都）科技服务有限公司 | C721: 港华舒适家（成都）科技服务有限公司 | D721: CNY | G721: TCHCD | H721: =COUNTIF(JV映射!$C:$C,$A721) -> 1 | I721: {=_xlfn.IFNA(INDEX(JV映射!$A:$A,MATCH($A721,JV映射!$C:$C,0)),"")} -> 201 | J721: =COUNTIF(CTP映射!$C:$C,$A721) -> 0 | K721: {=_xlfn.IFNA(INDEX(CTP映射!A:A,MATCH($A721,CTP映射!C:C,0)),"")} | L721: =VLOOKUP($A721,JV分部架构!$A:$F,5,0) -> ORG|EB_PRC | M721: =VLOOKUP($A721,JV分部架构!$A:$F,6,0) -> Extended Business - Mainland | N721: =VLOOKUP($A721,JV地区架构!$A:$F,5,0) -> LOC|MLC_51 | O721: =VLOOKUP($A721,JV地区架构!$A:$F,6,0) -> Sichuan | P721: =VLOOKUP($A721,JV数据源架构!$A:$F,5,0) -> #N/A | Q721: =VLOOKUP($A721,JV数据源架构!$A:$F,6,0) -> #N/A
A722: 01049 | B722: Yingkou Hong Kong and China Gas Co., Ltd. | C722: 营口港华燃气有限公司 | D722: CNY | G722: YKJV | H722: =COUNTIF(JV映射!$C:$C,$A722) -> 1 | I722: {=_xlfn.IFNA(INDEX(JV映射!$A:$A,MATCH($A722,JV映射!$C:$C,0)),"")} -> 022 | J722: =COUNTIF(CTP映射!$C:$C,$A722) -> 1 | K722: {=_xlfn.IFNA(INDEX(CTP映射!A:A,MATCH($A722,CTP映射!C:C,0)),"")} -> 022 | L722: =VLOOKUP($A722,JV分部架构!$A:$F,5,0) -> ORG|MU_GAS_TSEL | M722: =VLOOKUP($A722,JV分部架构!$A:$F,6,0) -> City Gas (TSEL) | N722: =VLOOKUP($A722,JV地区架构!$A:$F,5,0) -> LOC|MLC_21 | O722: =VLOOKUP($A722,JV地区架构!$A:$F,6,0) -> Liaoning | P722: =VLOOKUP($A722,JV数据源架构!$A:$F,5,0) -> SRC|DW_TMS | Q722: =VLOOKUP($A722,JV数据源架构!$A:$F,6,0) -> 通过DW上报TA（TMS）
A723: 01050 | B723: Ping Chang Hong Kong and China Gas Company Limited | C723: 平昌港华燃气有限公司 | D723: CNY | G723: SCPC | H723: =COUNTIF(JV映射!$C:$C,$A723) -> 1 | I723: {=_xlfn.IFNA(INDEX(JV映射!$A:$A,MATCH($A723,JV映射!$C:$C,0)),"")} -> 088 | J723: =COUNTIF(CTP映射!$C:$C,$A723) -> 1 | K723: {=_xlfn.IFNA(INDEX(CTP映射!A:A,MATCH($A723,CTP映射!C:C,0)),"")} -> 088 | L723: =VLOOKUP($A723,JV分部架构!$A:$F,5,0) -> ORG|MU_GAS_TSEL | M723: =VLOOKUP($A723,JV分部架构!$A:$F,6,0) -> City Gas (TSEL) | N723: =VLOOKUP($A723,JV地区架构!$A:$F,5,0) -> LOC|MLC_51 | O723: =VLOOKUP($A723,JV地区架构!$A:$F,6,0) -> Sichuan | P723: =VLOOKUP($A723,JV数据源架构!$A:$F,5,0) -> SRC|DW_TMS | Q723: =VLOOKUP($A723,JV数据源架构!$A:$F,6,0) -> 通过DW上报TA（TMS）
A724: 01051 | B724: Dalian Deta Towngas Co., Ltd. | C724: 大连德泰港华燃气股份有限公司 | D724: CNY | G724: DTJV | H724: =COUNTIF(JV映射!$C:$C,$A724) -> 1 | I724: {=_xlfn.IFNA(INDEX(JV映射!$A:$A,MATCH($A724,JV映射!$C:$C,0)),"")} -> DTJVR | J724: =COUNTIF(CTP映射!$C:$C,$A724) -> 1 | K724: {=_xlfn.IFNA(INDEX(CTP映射!A:A,MATCH($A724,CTP映射!C:C,0)),"")} -> 113 | L724: =VLOOKUP($A724,JV分部架构!$A:$F,5,0) -> ORG|MU_GAS_TSEL | M724: =VLOOKUP($A724,JV分部架构!$A:$F,6,0) -> City Gas (TSEL) | N724: =VLOOKUP($A724,JV地区架构!$A:$F,5,0) -> LOC|MLC_21 | O724: =VLOOKUP($A724,JV地区架构!$A:$F,6,0) -> Liaoning | P724: =VLOOKUP($A724,JV数据源架构!$A:$F,5,0) -> SRC|DW_TMS | Q724: =VLOOKUP($A724,JV数据源架构!$A:$F,6,0) -> 通过DW上报TA（TMS）
A725: 01052 | B725: Towngas (BVI) Holdings Limited | C725: 港华燃气（维尔京）控股有限公司 | D725: HKD | G725: TGHL | H725: =COUNTIF(JV映射!$C:$C,$A725) -> 0 | I725: {=_xlfn.IFNA(INDEX(JV映射!$A:$A,MATCH($A725,JV映射!$C:$C,0)),"")} | J725: =COUNTIF(CTP映射!$C:$C,$A725) -> 1 | K725: {=_xlfn.IFNA(INDEX(CTP映射!A:A,MATCH($A725,CTP映射!C:C,0)),"")} -> JYGLF0602 | L725: =VLOOKUP($A725,JV分部架构!$A:$F,5,0) -> ORG|OTHER | M725: =VLOOKUP($A725,JV分部架构!$A:$F,6,0) -> Other Businesses | N725: =VLOOKUP($A725,JV地区架构!$A:$F,5,0) -> LOC|BVI | O725: =VLOOKUP($A725,JV地区架构!$A:$F,6,0) -> BVI | P725: =VLOOKUP($A725,JV数据源架构!$A:$F,5,0) -> SRC|HK_SAP | Q725: =VLOOKUP($A725,JV数据源架构!$A:$F,6,0) -> SAP直接上报TA
A726: 01053 | B726: Hong Kong and China Gas (Dalian) Limited | C726: 香港中华煤气（大连）有限公司 | D726: HKD | G726: HKDL | H726: =COUNTIF(JV映射!$C:$C,$A726) -> 0 | I726: {=_xlfn.IFNA(INDEX(JV映射!$A:$A,MATCH($A726,JV映射!$C:$C,0)),"")} | J726: =COUNTIF(CTP映射!$C:$C,$A726) -> 1 | K726: {=_xlfn.IFNA(INDEX(CTP映射!A:A,MATCH($A726,CTP映射!C:C,0)),"")} -> JYGLF0597 | L726: =VLOOKUP($A726,JV分部架构!$A:$F,5,0) -> ORG|OTHER | M726: =VLOOKUP($A726,JV分部架构!$A:$F,6,0) -> Other Businesses | N726: =VLOOKUP($A726,JV地区架构!$A:$F,5,0) -> LOC|HK | O726: =VLOOKUP($A726,JV地区架构!$A:$F,6,0) -> Hong Kong | P726: =VLOOKUP($A726,JV数据源架构!$A:$F,5,0) -> SRC|HK_SAP | Q726: =VLOOKUP($A726,JV数据源架构!$A:$F,6,0) -> SAP直接上报TA
A727: 01055 | B727: Chengdu Gas Group Corporation Ltd. | C727: 成都燃气集团股份有限公司 | D727: CNY | H727: =COUNTIF(JV映射!$C:$C,$A727) -> 1 | I727: {=_xlfn.IFNA(INDEX(JV映射!$A:$A,MATCH($A727,JV映射!$C:$C,0)),"")} -> 092 | J727: =COUNTIF(CTP映射!$C:$C,$A727) -> 1 | K727: {=_xlfn.IFNA(INDEX(CTP映射!A:A,MATCH($A727,CTP映射!C:C,0)),"")} -> JYGLF0007 | L727: =VLOOKUP($A727,JV分部架构!$A:$F,5,0) -> ORG|MU_GAS_TSEL | M727: =VLOOKUP($A727,JV分部架构!$A:$F,6,0) -> City Gas (TSEL) | N727: =VLOOKUP($A727,JV地区架构!$A:$F,5,0) -> LOC|MLC_51 | O727: =VLOOKUP($A727,JV地区架构!$A:$F,6,0) -> Sichuan | P727: =VLOOKUP($A727,JV数据源架构!$A:$F,5,0) -> #N/A | Q727: =VLOOKUP($A727,JV数据源架构!$A:$F,6,0) -> #N/A
A728: 01056 | B728: Dalian Changxing Hong Kong and China Gas Co. Ltd. | C728: 大连长兴港华燃气有限公司 | D728: CNY | G728: DLCXJV | H728: =COUNTIF(JV映射!$C:$C,$A728) -> 1 | I728: {=_xlfn.IFNA(INDEX(JV映射!$A:$A,MATCH($A728,JV映射!$C:$C,0)),"")} -> 024 | J728: =COUNTIF(CTP映射!$C:$C,$A728) -> 1 | K728: {=_xlfn.IFNA(INDEX(CTP映射!A:A,MATCH($A728,CTP映射!C:C,0)),"")} -> 024 | L728: =VLOOKUP($A728,JV分部架构!$A:$F,5,0) -> ORG|MU_GAS_TSEL | M728: =VLOOKUP($A728,JV分部架构!$A:$F,6,0) -> City Gas (TSEL) | N728: =VLOOKUP($A728,JV地区架构!$A:$F,5,0) -> LOC|MLC_21 | O728: =VLOOKUP($A728,JV地区架构!$A:$F,6,0) -> Liaoning | P728: =VLOOKUP($A728,JV数据源架构!$A:$F,5,0) -> SRC|DW_TMS | Q728: =VLOOKUP($A728,JV数据源架构!$A:$F,6,0) -> 通过DW上报TA（TMS）
...

Sheet JV分部架构
A1: Entity list | B1: Entity list - Description | C1: Hierarchy | D1: Hierarchy - Description | E1: Node | F1: Node - Description
A2: 00001 | B2: The Hong Kong and China Gas Company Limited | C2: ORG | D2: Entity-Segment | E2: ORG|HK_CORE | F2: Hong Kong Business
A3: 00002 | B3: Skyward Investments Limited | C3: ORG | D3: Entity-Segment | E3: ORG|HK_BUSINESS | F3: HK Business
A4: 00003 | B4: Brilliant World International Limited | C4: ORG | D4: Entity-Segment | E4: ORG|HK_BUSINESS | F4: HK Business
A5: 00004 | B5: Edonlite Holdings Limited | C5: ORG | D5: Entity-Segment | E5: ORG|HK_BUSINESS | F5: HK Business
A6: 00005 | B6: Primebay Investments Limited | C6: ORG | D6: Entity-Segment | E6: ORG|HK_BUSINESS | F6: HK Business
A7: 00006 | B7: China Guide Resources Limited | C7: ORG | D7: Entity-Segment | E7: ORG|HK_BUSINESS | F7: HK Business
A8: 00007 | B8: Smoothing Investment Limited | C8: ORG | D8: Entity-Segment | E8: ORG|HK_BUSINESS | F8: HK Business
A9: 00008 | B9: Quality Testing Services Limited | C9: ORG | D9: Entity-Segment | E9: ORG|HK_BUSINESS | F9: HK Business
A10: 00009 | B10: P-Tech Engineering Company Limited | C10: ORG | D10: Entity-Segment | E10: ORG|P_TECH | F10: P-Tech
A11: 00010 | B11: China Gas Company Limited | C11: ORG | D11: Entity-Segment | E11: ORG|HK_BUSINESS | F11: HK Business
A12: 00011 | B12: Hong Kong Gas Company Limited | C12: ORG | D12: Entity-Segment | E12: ORG|HK_BUSINESS | F12: HK Business
... A857: MA_00300-91 | B857: Hong Kong & China Gas Investment Limited(SZ OFFICE) | C857: ORG | D857: Entity-Segment | E857: ORG|MU | F857: Mainland Business

Sheet JV地区架构
A1: Entity list | B1: Entity list - Description | C1: Hierarchy | D1: Hierarchy - Description | E1: Node | F1: Node - Description
A2: 00001 | B2: The Hong Kong and China Gas Company Limited | C2: LOC | D2: Location | E2: LOC|HK | F2: Hong Kong
A3: 00002 | B3: Skyward Investments Limited | C3: LOC | D3: Location | E3: LOC|HK | F3: Hong Kong
A4: 00003 | B4: Brilliant World International Limited | C4: LOC | D4: Location | E4: LOC|BVI | F4: BVI
A5: 00004 | B5: Edonlite Holdings Limited | C5: LOC | D5: Location | E5: LOC|BVI | F5: BVI
A6: 00005 | B6: Primebay Investments Limited | C6: LOC | D6: Location | E6: LOC|BVI | F6: BVI
A7: 00006 | B7: China Guide Resources Limited | C7: LOC | D7: Location | E7: LOC|HK | F7: Hong Kong
A8: 00007 | B8: Smoothing Investment Limited | C8: LOC | D8: Location | E8: LOC|HK | F8: Hong Kong
A9: 00008 | B9: Quality Testing Services Limited | C9: LOC | D9: Location | E9: LOC|HK | F9: Hong Kong
A10: 00009 | B10: P-Tech Engineering Company Limited | C10: LOC | D10: Location | E10: LOC|HK | F10: Hong Kong
A11: 00010 | B11: China Gas Company Limited | C11: LOC | D11: Location | E11: LOC|HK | F11: Hong Kong
A12: 00011 | B12: Hong Kong Gas Company Limited | C12: LOC | D12: Location | E12: LOC|HK | F12: Hong Kong
... A841: 02278 | B841: 深圳港华慧能科技有限公司（合并） | C841: LOC | D841: Location | E841: LOC|MLC_44 | F841: Guangdong

Sheet JV数据源架构
A1: Entity list | B1: Entity list - Description | C1: Hierarchy | D1: Hierarchy - Description | E1: Node | F1: Node - Description
A2: 00001 | B2: The Hong Kong and China Gas Company Limited | C2: SRC | D2: Source | E2: SRC|HK_SAP | F2: SAP直接上报TA
A3: 00002 | B3: Skyward Investments Limited | C3: SRC | D3: Source | E3: SRC|HK_SAP | F3: SAP直接上报TA
A4: 00003 | B4: Brilliant World International Limited | C4: SRC | D4: Source | E4: SRC|HK_SAP | F4: SAP直接上报TA
A5: 00004 | B5: Edonlite Holdings Limited | C5: SRC | D5: Source | E5: SRC|HK_SAP | F5: SAP直接上报TA
A6: 00005 | B6: Primebay Investments Limited | C6: SRC | D6: Source | E6: SRC|HK_SAP | F6: SAP直接上报TA
A7: 00006 | B7: China Guide Resources Limited | C7: SRC | D7: Source | E7: SRC|HK_SAP | F7: SAP直接上报TA
A8: 00007 | B8: Smoothing Investment Limited | C8: SRC | D8: Source | E8: SRC|HK_SAP | F8: SAP直接上报TA
A9: 00008 | B9: Quality Testing Services Limited | C9: SRC | D9: Source | E9: SRC|HK_SAP | F9: SAP直接上报TA
A10: 00009 | B10: P-Tech Engineering Company Limited | C10: SRC | D10: Source | E10: SRC|HK_SAP | F10: SAP直接上报TA
A11: 00010 | B11: China Gas Company Limited | C11: SRC | D11: Source | E11: SRC|HK_SAP | F11: SAP直接上报TA
A12: 00011 | B12: Hong Kong Gas Company Limited | C12: SRC | D12: Source | E12: SRC|HK_SAP | F12: SAP直接上报TA
... A833: MA_00300-91 | B833: Hong Kong & China Gas Investment Limited(SZ OFFICE) | C833: SRC | D833: Source | E833: SRC|XX_DUMMY | F833: Dummy Entity

Sheet JV映射
A1: Input 1 - TMS_ENTI | B1: Description Input 1 - TMS_ENTI | C1: Output 1 - TA_ENTI | D1: Description Output 1 - TA_ENTI | E1: mat
A2: 00209 | C2: 00375 | D2: 名气家投资有限公司 | E2: =VLOOKUP(C2,CTP映射!C:D,2,FALSE) -> 名气家投资有限公司
A3: 00210 | C3: 00331 | D3: 港华国际能源贸易有限公司 | E3: =VLOOKUP(C3,CTP映射!C:D,2,FALSE) -> 港华国际能源贸易有限公司
A4: 006 | C4: 00930 | D4: 安庆港华燃气有限公司 | E4: =VLOOKUP(C4,CTP映射!C:D,2,FALSE) -> 安庆港华燃气有限公司
A5: 007 | C5: 00285 | D5: 安徽省天然气开发股份有限公司 | E5: =VLOOKUP(C5,CTP映射!C:D,2,FALSE) -> 安徽省天然气开发股份有限公司
A6: 009 | C6: 00968 | D6: 黄山港华燃气有限公司 | E6: =VLOOKUP(C6,CTP映射!C:D,2,FALSE) -> 黄山港华燃气有限公司
A7: 010 | C7: 00967 | D7: 黄山太平港华燃气有限公司 | E7: =VLOOKUP(C7,CTP映射!C:D,2,FALSE) -> 黄山太平港华燃气有限公司
A8: 011 | C8: 00969 | D8: 黄山徽州港华燃气有限公司 | E8: =VLOOKUP(C8,CTP映射!C:D,2,FALSE) -> 黄山徽州港华燃气有限公司
A9: 012 | C9: 00918 | D9: 马鞍山博望港华燃气有限公司 | E9: =VLOOKUP(C9,CTP映射!C:D,2,FALSE) -> 马鞍山博望港华燃气有限公司
A10: 014 | C10: 00275 | D10: 张家港港华燃气有限公司 | E10: =VLOOKUP(C10,CTP映射!C:D,2,FALSE) -> 张家港港华燃气有限公司
A11: 015 | C11: 00287 | D11: 吴江港华燃气有限公司 | E11: =VLOOKUP(C11,CTP映射!C:D,2,FALSE) -> 吴江港华燃气有限公司
A12: 01902 | C12: 00607 | D12: 铁岭港能投智慧能源有限公司 | E12: =VLOOKUP(C12,CTP映射!C:D,2,FALSE) -> 铁岭港能投智慧能源有限公司
A13: 022 | C13: 01049 | D13: 营口港华燃气有限公司 | E13: =VLOOKUP(C13,CTP映射!C:D,2,FALSE) -> 营口港华燃气有限公司
... A433: ZSJV | C433: 00271 | D433: 中山港华燃气有限公司 | E433: =VLOOKUP(C433,CTP映射!C:D,2,FALSE) -> 中山港华燃气有限公司

Sheet CTP映射
A1: Input 1 - TMS_CTP | B1: Description Input 1 - TMS_CTP | C1: Output 1 - TA_CTP | D1: Description Output 1 - TA_CTP
A2: 002 | C2: 00300 | D2: 港华投资有限公司
A3: 00201 | C3: 00378 | D3: 卓锐智高（武汉）科技有限公司
A4: 002012 | C4: 00344 | D4: 宿迁港能投光伏有限公司
A5: 00201201 | C5: 00372 | D5: 宿迁迅途能源有限公司
A6: 00201202 | C6: 00383 | D6: 宿迁鑫洲新能源有限公司 | F6: 1865
A7: 00202 | C7: 00322 | D7: 广州港华燃气科技服务有限公司 | F7: 432
A8: 00203 | C8: 00321 | D8: 港华紫荆燃具（深圳）有限公司
A9: 00204 | C9: 00310 | D9: 沈阳三全工程监理咨询有限公司
A10: 0020406 | C10: 01720 | D10: 沈阳三全工程监理咨询有限公司徐州分公司
A11: 00205 | C11: 00324 | D11: 深圳市燃气用具有限公司
A12: 00206 | C12: 00325 | D12: 中新苏州工业园区开发集团股份有限公司
A13: 00209 | C13: 00328 | D13: 名气家信息服务有限公司
A14: 0020902 | C14: 01198 | D14: 名气家（上海）数字科技有限公司
A15: 0020903 | C15: 01245 | D15: 港华到家（广东）信息技术有限公司
A16: 002090301 | C16: 02236 | D16: 清远名气家生活服务有限公司
A17: 002090302 | C17: 01743 | D17: 港华到家（广东）信息技术有限公司广州番禺桥南店
A18: 002090303 | C18: 01744 | D18: 港华到家（广东）信息技术有限公司广州东永天琅店
A19: 002090304 | C19: 01247 | D19: 港华到家（中山）信息科技有限公司
... A1866: SW00806 | C1866: 00360 | D1866: 江苏道胜市容环境服务有限公司

Sheet 公司清单
A1: Company List | F1: 与JV的关系
A2: Code | B2: English Description | C2: 中文 description | D2: Start date | E2: End date | F2: 是否JV/CTP | G2: 归属Entity/JV | H2: 归属Entity/JV名称
A3: 00001 | B3: The Hong Kong and China Gas Company Limited | C3: 香港中华煤气有限公司 | F3: =_xlfn.IFNA(IF(MATCH(A3,'JV and CTP清单'!A:A,0)>0,"是",""),"否") -> 是 | G3: =_xlfn.IFNA(VLOOKUP($A3,公司与JV对应关系!$A:$D,3,0),"") | H3: =_xlfn.IFNA(VLOOKUP($A3,公司与JV对应关系!$A:$D,4,0),"")
A4: 00002 | B4: Skyward Investments Limited | C4: Skyward Investments Limited | F4: =_xlfn.IFNA(IF(MATCH(A4,'JV and CTP清单'!A:A,0)>0,"是",""),"否") -> 是 | G4: =_xlfn.IFNA(VLOOKUP($A4,公司与JV对应关系!$A:$D,3,0),"") | H4: =_xlfn.IFNA(VLOOKUP($A4,公司与JV对应关系!$A:$D,4,0),"")
A5: 00003 | B5: Brilliant World International Limited | C5: Brilliant World International Limited | F5: =_xlfn.IFNA(IF(MATCH(A5,'JV and CTP清单'!A:A,0)>0,"是",""),"否") -> 是 | G5: =_xlfn.IFNA(VLOOKUP($A5,公司与JV对应关系!$A:$D,3,0),"") | H5: =_xlfn.IFNA(VLOOKUP($A5,公司与JV对应关系!$A:$D,4,0),"")
A6: 00004 | B6: Edonlite Holdings Limited | C6: Edonlite Holdings Limited | F6: =_xlfn.IFNA(IF(MATCH(A6,'JV and CTP清单'!A:A,0)>0,"是",""),"否") -> 是 | G6: =_xlfn.IFNA(VLOOKUP($A6,公司与JV对应关系!$A:$D,3,0),"") | H6: =_xlfn.IFNA(VLOOKUP($A6,公司与JV对应关系!$A:$D,4,0),"")
A7: 00005 | B7: Primebay Investments Limited | C7: Primebay Investments Limited | F7: =_xlfn.IFNA(IF(MATCH(A7,'JV and CTP清单'!A:A,0)>0,"是",""),"否") -> 是 | G7: =_xlfn.IFNA(VLOOKUP($A7,公司与JV对应关系!$A:$D,3,0),"") | H7: =_xlfn.IFNA(VLOOKUP($A7,公司与JV对应关系!$A:$D,4,0),"")
A8: 00006 | B8: China Guide Resources Limited | C8: 中诚资源有限公司 | F8: =_xlfn.IFNA(IF(MATCH(A8,'JV and CTP清单'!A:A,0)>0,"是",""),"否") -> 是 | G8: =_xlfn.IFNA(VLOOKUP($A8,公司与JV对应关系!$A:$D,3,0),"") | H8: =_xlfn.IFNA(VLOOKUP($A8,公司与JV对应关系!$A:$D,4,0),"")
A9: 00007 | B9: Smoothing Investment Limited | C9: 伟诚倡投资有限公司 | F9: =_xlfn.IFNA(IF(MATCH(A9,'JV and CTP清单'!A:A,0)>0,"是",""),"否") -> 是 | G9: =_xlfn.IFNA(VLOOKUP($A9,公司与JV对应关系!$A:$D,3,0),"") | H9: =_xlfn.IFNA(VLOOKUP($A9,公司与JV对应关系!$A:$D,4,0),"")
A10: 00008 | B10: Quality Testing Services Limited | C10: 质量测检服务有限公司 | F10: =_xlfn.IFNA(IF(MATCH(A10,'JV and CTP清单'!A:A,0)>0,"是",""),"否") -> 是 | G10: =_xlfn.IFNA(VLOOKUP($A10,公司与JV对应关系!$A:$D,3,0),"") | H10: =_xlfn.IFNA(VLOOKUP($A10,公司与JV对应关系!$A:$D,4,0),"")
A11: 00009 | B11: P-Tech Engineering Company Limited | C11: 卓诚工程有限公司 | F11: =_xlfn.IFNA(IF(MATCH(A11,'JV and CTP清单'!A:A,0)>0,"是",""),"否") -> 是 | G11: =_xlfn.IFNA(VLOOKUP($A11,公司与JV对应关系!$A:$D,3,0),"") | H11: =_xlfn.IFNA(VLOOKUP($A11,公司与JV对应关系!$A:$D,4,0),"")
A12: 00010 | B12: China Gas Company Limited | C12: 中华煤气有限公司 | F12: =_xlfn.IFNA(IF(MATCH(A12,'JV and CTP清单'!A:A,0)>0,"是",""),"否") -> 是 | G12: =_xlfn.IFNA(VLOOKUP($A12,公司与JV对应关系!$A:$D,3,0),"") | H12: =_xlfn.IFNA(VLOOKUP($A12,公司与JV对应关系!$A:$D,4,0),"")
A13: 00011 | B13: Hong Kong Gas Company Limited | C13: 香港煤气有限公司 | F13: =_xlfn.IFNA(IF(MATCH(A13,'JV and CTP清单'!A:A,0)>0,"是",""),"否") -> 是 | G13: =_xlfn.IFNA(VLOOKUP($A13,公司与JV对应关系!$A:$D,3,0),"") | H13: =_xlfn.IFNA(VLOOKUP($A13,公司与JV对应关系!$A:$D,4,0),"")
A14: 00012 | B14: Alpha Idea International Limited | C14: 星满国际有限公司 | F14: =_xlfn.IFNA(IF(MATCH(A14,'JV and CTP清单'!A:A,0)>0,"是",""),"否") -> 是 | G14: =_xlfn.IFNA(VLOOKUP($A14,公司与JV对应关系!$A:$D,3,0),"") | H14: =_xlfn.IFNA(VLOOKUP($A14,公司与JV对应关系!$A:$D,4,0),"")
... A779: 00777 | B779: 宁波盛凯能源科技有限公司 | C779: 宁波盛凯能源科技有限公司 | F779: =_xlfn.IFNA(IF(MATCH(A779,'JV and CTP清单'!A:A,0)>0,"是",""),"否") -> 是 | G779: =_xlfn.IFNA(VLOOKUP($A779,公司与JV对应关系!$A:$D,3,0),"") | H779: =_xlfn.IFNA(VLOOKUP($A779,公司与JV对应关系!$A:$D,4,0),"")
A780: 00778 | B780: 宣城坤能新能源科技有限公司（重复，停用） | C780: 宣城坤能新能源科技有限公司（重复，停用） | E780: 44926 | F780: =_xlfn.IFNA(IF(MATCH(A780,'JV and CTP清单'!A:A,0)>0,"是",""),"否") -> 是 | G780: =_xlfn.IFNA(VLOOKUP($A780,公司与JV对应关系!$A:$D,3,0),"") | H780: =_xlfn.IFNA(VLOOKUP($A780,公司与JV对应关系!$A:$D,4,0),"")
A781: 00779 | B781: 徐州普未光合能源科技有限公司 | C781: 徐州普未光合能源科技有限公司 | F781: =_xlfn.IFNA(IF(MATCH(A781,'JV and CTP清单'!A:A,0)>0,"是",""),"否") -> 是 | G781: =_xlfn.IFNA(VLOOKUP($A781,公司与JV对应关系!$A:$D,3,0),"") | H781: =_xlfn.IFNA(VLOOKUP($A781,公司与JV对应关系!$A:$D,4,0),"")
A782: 00780 | B782: 上海兆熙新能源科技有限公司 | C782: 上海兆熙新能源科技有限公司 | F782: =_xlfn.IFNA(IF(MATCH(A782,'JV and CTP清单'!A:A,0)>0,"是",""),"否") -> 是 | G782: =_xlfn.IFNA(VLOOKUP($A782,公司与JV对应关系!$A:$D,3,0),"") | H782: =_xlfn.IFNA(VLOOKUP($A782,公司与JV对应关系!$A:$D,4,0),"")
A783: 00781 | B783: 温州狮耀新能源有限公司 | C783: 温州狮耀新能源有限公司 | F783: =_xlfn.IFNA(IF(MATCH(A783,'JV and CTP清单'!A:A,0)>0,"是",""),"否") -> 是 | G783: =_xlfn.IFNA(VLOOKUP($A783,公司与JV对应关系!$A:$D,3,0),"") | H783: =_xlfn.IFNA(VLOOKUP($A783,公司与JV对应关系!$A:$D,4,0),"")
A784: 00782 | B784: 丹阳市晶能光伏电力有限公司 | C784: 丹阳市晶能光伏电力有限公司 | F784: =_xlfn.IFNA(IF(MATCH(A784,'JV and CTP清单'!A:A,0)>0,"是",""),"否") -> 是 | G784: =_xlfn.IFNA(VLOOKUP($A784,公司与JV对应关系!$A:$D,3,0),"") | H784: =_xlfn.IFNA(VLOOKUP($A784,公司与JV对应关系!$A:$D,4,0),"")
A785: 00783 | B785: 镇江市中盛清洁能源有限公司 | C785: 镇江市中盛清洁能源有限公司 | F785: =_xlfn.IFNA(IF(MATCH(A785,'JV and CTP清单'!A:A,0)>0,"是",""),"否") -> 是 | G785: =_xlfn.IFNA(VLOOKUP($A785,公司与JV对应关系!$A:$D,3,0),"") | H785: =_xlfn.IFNA(VLOOKUP($A785,公司与JV对应关系!$A:$D,4,0),"")
A786: 00784 | B786: 睢宁县晶能光伏电力有限公司 | C786: 睢宁县晶能光伏电力有限公司 | F786: =_xlfn.IFNA(IF(MATCH(A786,'JV and CTP清单'!A:A,0)>0,"是",""),"否") -> 是 | G786: =_xlfn.IFNA(VLOOKUP($A786,公司与JV对应关系!$A:$D,3,0),"") | H786: =_xlfn.IFNA(VLOOKUP($A786,公司与JV对应关系!$A:$D,4,0),"")
A787: 00785 | B787: 常州科鸿光伏电力有限公司 | C787: 常州科鸿光伏电力有限公司 | F787: =_xlfn.IFNA(IF(MATCH(A787,'JV and CTP清单'!A:A,0)>0,"是",""),"否") -> 是 | G787: =_xlfn.IFNA(VLOOKUP($A787,公司与JV对应关系!$A:$D,3,0),"") | H787: =_xlfn.IFNA(VLOOKUP($A787,公司与JV对应关系!$A:$D,4,0),"")
A788: 00786 | B788: 凤阳纤安新能源有限公司 | C788: 凤阳纤安新能源有限公司 | F788: =_xlfn.IFNA(IF(MATCH(A788,'JV and CTP清单'!A:A,0)>0,"是",""),"否") -> 是 | G788: =_xlfn.IFNA(VLOOKUP($A788,公司与JV对应关系!$A:$D,3,0),"") | H788: =_xlfn.IFNA(VLOOKUP($A788,公司与JV对应关系!$A:$D,4,0),"")
A789: 00787 | B789: 武汉国楚云天新能源有限公司 | C789: 武汉国楚云天新能源有限公司 | F789: =_xlfn.IFNA(IF(MATCH(A789,'JV and CTP清单'!A:A,0)>0,"是",""),"否") -> 是 | G789: =_xlfn.IFNA(VLOOKUP($A789,公司与JV对应关系!$A:$D,3,0),"") | H789: =_xlfn.IFNA(VLOOKUP($A789,公司与JV对应关系!$A:$D,4,0),"")
A790: 00788 | B790: 宿州百嘉光伏科技有限公司 | C790: 宿州百嘉光伏科技有限公司 | F790: =_xlfn.IFNA(IF(MATCH(A790,'JV and CTP清单'!A:A,0)>0,"是",""),"否") -> 是 | G790: =_xlfn.IFNA(VLOOKUP($A790,公司与JV对应关系!$A:$D,3,0),"") | H790: =_xlfn.IFNA(VLOOKUP($A790,公司与JV对应关系!$A:$D,4,0),"")
A791: 00789 | B791: 宁波森康能源科技有限公司 | C791: 宁波森康能源科技有限公司 | F791: =_xlfn.IFNA(IF(MATCH(A791,'JV and CTP清单'!A:A,0)>0,"是",""),"否") -> 否 | G791: =_xlfn.IFNA(VLOOKUP($A791,公司与JV对应关系!$A:$D,3,0),"") -> 00765 | H791: =_xlfn.IFNA(VLOOKUP($A791,公司与JV对应关系!$A:$D,4,0),"") -> 宁波联阔新能源有限公司
A792: 00790 | B792: 余姚南泰光伏发电有限公司 | C792: 余姚南泰光伏发电有限公司 | F792: =_xlfn.IFNA(IF(MATCH(A792,'JV and CTP清单'!A:A,0)>0,"是",""),"否") -> 否 | G792: =_xlfn.IFNA(VLOOKUP($A792,公司与JV对应关系!$A:$D,3,0),"") -> 00765 | H792: =_xlfn.IFNA(VLOOKUP($A792,公司与JV对应关系!$A:$D,4,0),"") -> 宁波联阔新能源有限公司
... A1827: 01825 | B1827: 西安秦华天然气有限公司 | C1827: 西安秦华天然气有限公司 | F1827: =_xlfn.IFNA(IF(MATCH(A1827,'JV and CTP清单'!A:A,0)>0,"是",""),"否") -> 否 | G1827: =_xlfn.IFNA(VLOOKUP($A1827,公司与JV对应关系!$A:$D,3,0),"") | H1827: =_xlfn.IFNA(VLOOKUP($A1827,公司与JV对应关系!$A:$D,4,0),"")
A1828: 01826 | B1828: 大连德泰港能投智慧能源有限公司（重复，停用） | C1828: 大连德泰港能投智慧能源有限公司（重复，停用） | E1828: 44926 | F1828: =_xlfn.IFNA(IF(MATCH(A1828,'JV and CTP清单'!A:A,0)>0,"是",""),"否") -> 是 | G1828: =_xlfn.IFNA(VLOOKUP($A1828,公司与JV对应关系!$A:$D,3,0),"") | H1828: =_xlfn.IFNA(VLOOKUP($A1828,公司与JV对应关系!$A:$D,4,0),"")
A1829: 01827 | B1829: 佛山市燃气集团股份有限公司 | C1829: 佛山市燃气集团股份有限公司 | F1829: =_xlfn.IFNA(IF(MATCH(A1829,'JV and CTP清单'!A:A,0)>0,"是",""),"否") -> 是 | G1829: =_xlfn.IFNA(VLOOKUP($A1829,公司与JV对应关系!$A:$D,3,0),"") | H1829: =_xlfn.IFNA(VLOOKUP($A1829,公司与JV对应关系!$A:$D,4,0),"")
A1830: 01828 | B1830: 潮州枫溪深能港华燃气有限公司 | C1830: 潮州枫溪深能港华燃气有限公司 | F1830: =_xlfn.IFNA(IF(MATCH(A1830,'JV and CTP清单'!A:A,0)>0,"是",""),"否") -> 是 | G1830: =_xlfn.IFNA(VLOOKUP($A1830,公司与JV对应关系!$A:$D,3,0),"") -> 01183 | H1830: =_xlfn.IFNA(VLOOKUP($A1830,公司与JV对应关系!$A:$D,4,0),"") -> 潮州深能港华燃气有限公司
A1831: 01829 | B1831: 武汉市车都天然气有限公司 | C1831: 武汉市车都天然气有限公司 | F1831: =_xlfn.IFNA(IF(MATCH(A1831,'JV and CTP清单'!A:A,0)>0,"是",""),"否") -> 是 | G1831: =_xlfn.IFNA(VLOOKUP($A1831,公司与JV对应关系!$A:$D,3,0),"") | H1831: =_xlfn.IFNA(VLOOKUP($A1831,公司与JV对应关系!$A:$D,4,0),"")
A1832: 01830 | B1832: 石家庄建投天然气有限公司 | C1832: 石家庄建投天然气有限公司 | F1832: =_xlfn.IFNA(IF(MATCH(A1832,'JV and CTP清单'!A:A,0)>0,"是",""),"否") -> 是 | G1832: =_xlfn.IFNA(VLOOKUP($A1832,公司与JV对应关系!$A:$D,3,0),"") | H1832: =_xlfn.IFNA(VLOOKUP($A1832,公司与JV对应关系!$A:$D,4,0),"")
A1833: 01831 | B1833: 承德市建投天然气有限责任公司 | C1833: 承德市建投天然气有限责任公司 | F1833: =_xlfn.IFNA(IF(MATCH(A1833,'JV and CTP清单'!A:A,0)>0,"是",""),"否") -> 是 | G1833: =_xlfn.IFNA(VLOOKUP($A1833,公司与JV对应关系!$A:$D,3,0),"") -> 00286 | H1833: =_xlfn.IFNA(VLOOKUP($A1833,公司与JV对应关系!$A:$D,4,0),"") -> Hebei Natural Gas Company Limited
A1834: 01832 | B1834: 清河县建投天然气有限公司 | C1834: 清河县建投天然气有限公司 | F1834: =_xlfn.IFNA(IF(MATCH(A1834,'JV and CTP清单'!A:A,0)>0,"是",""),"否") -> 是 | G1834: =_xlfn.IFNA(VLOOKUP($A1834,公司与JV对应关系!$A:$D,3,0),"") -> 00286 | H1834: =_xlfn.IFNA(VLOOKUP($A1834,公司与JV对应关系!$A:$D,4,0),"") -> Hebei Natural Gas Company Limited
A1835: 01833 | B1835: 晋州市建投燃气有限公司 | C1835: 晋州市建投燃气有限公司 | F1835: =_xlfn.IFNA(IF(MATCH(A1835,'JV and CTP清单'!A:A,0)>0,"是",""),"否") -> 是 | G1835: =_xlfn.IFNA(VLOOKUP($A1835,公司与JV对应关系!$A:$D,3,0),"") -> 00286 | H1835: =_xlfn.IFNA(VLOOKUP($A1835,公司与JV对应关系!$A:$D,4,0),"") -> Hebei Natural Gas Company Limited
A1836: 01834 | B1836: 深州市建投燃气有限公司 | C1836: 深州市建投燃气有限公司 | F1836: =_xlfn.IFNA(IF(MATCH(A1836,'JV and CTP清单'!A:A,0)>0,"是",""),"否") -> 是 | G1836: =_xlfn.IFNA(VLOOKUP($A1836,公司与JV对应关系!$A:$D,3,0),"") -> 00286 | H1836: =_xlfn.IFNA(VLOOKUP($A1836,公司与JV对应关系!$A:$D,4,0),"") -> Hebei Natural Gas Company Limited
A1837: 01835 | B1837: 宁晋县建投天然气有限责任公司 | C1837: 宁晋县建投天然气有限责任公司 | F1837: =_xlfn.IFNA(IF(MATCH(A1837,'JV and CTP清单'!A:A,0)>0,"是",""),"否") -> 是 | G1837: =_xlfn.IFNA(VLOOKUP($A1837,公司与JV对应关系!$A:$D,3,0),"") | H1837: =_xlfn.IFNA(VLOOKUP($A1837,公司与JV对应关系!$A:$D,4,0),"")
A1838: 01836 | B1838: 临西县新能天然气工程有限公司 | C1838: 临西县新能天然气工程有限公司 | F1838: =_xlfn.IFNA(IF(MATCH(A1838,'JV and CTP清单'!A:A,0)>0,"是",""),"否") -> 否 | G1838: =_xlfn.IFNA(VLOOKUP($A1838,公司与JV对应关系!$A:$D,3,0),"") | H1838: =_xlfn.IFNA(VLOOKUP($A1838,公司与JV对应关系!$A:$D,4,0),"")
...

Sheet 公司与JV对应关系
A1: Company (Subsidiary) | C1: Entity (JV) | E1: Start Period | F1: End Period
A2: 00455 | B2: Lane Success Development Limited | C2: 00044 | D2: Monarch Properties Limited
A3: 00134 | B3: ECO Orient Energy (Thailand) Ltd. | C3: 00135 | D3: ECO Orient Resources (Thailand) Ltd.
A4: 00462 | B4: EcoCeres, Inc. | C4: 00195 | D4: EcoCeres, Inc.
A5: 00465 | B5: Everwealth Investment Management, Inc. | C5: 00195 | D5: EcoCeres, Inc.
A6: 00466 | B6: ECO Bio-Grease Utilization Company Limited | C6: 00195 | D6: EcoCeres, Inc.
A7: 00467 | B7: ECO Agricultural Resources Utilization Company Limited | C7: 00195 | D7: EcoCeres, Inc.
A8: 00468 | B8: ECO Trading Investments Limited | C8: 00195 | D8: EcoCeres, Inc.
A9: 00469 | B9: ECO Energy Resources Limited | C9: 00195 | D9: EcoCeres, Inc.
A10: 00470 | B10: ECO Bio-Grease (Zhangjiagang) Investments Company Limited | C10: 00195 | D10: EcoCeres, Inc.
A11: 00471 | B11: ECO Green Hydrogen Investments Company Limited | C11: 00195 | D11: EcoCeres, Inc.
A12: 00472 | B12: ECO Biotechnology Investments Company Limited | C12: 00195 | D12: EcoCeres, Inc.
A13: 00473 | B13: ECO Biofuel Technology Investments Company Limited | C13: 00195 | D13: EcoCeres, Inc.
... A796: 02261 | B796: 深汭（上海）综合能源服务有限公司 | C796: 02278 | D796: 深圳港华慧能科技有限公司

Sheet 各板块数据
A1: 板块 | B1: 单位名称 | C1: TA匹配 | D1: MT
A2: MU | B2: 国家管网集团吉林天然气管道有限责任公司 | C2: =VLOOKUP(B2,公司清单!C:C,1,FALSE) -> #N/A | D2: =VLOOKUP(B2,'JV and CTP清单'!C:C,1,FALSE) -> #N/A
A3: MU | B3: 吉林港华清洁能源有限公司 | C3: =VLOOKUP(B3,公司清单!C:C,1,FALSE) -> 吉林港华清洁能源有限公司 | D3: =VLOOKUP(B3,'JV and CTP清单'!C:C,1,FALSE) -> #N/A
A4: MU | B4: 石家庄建投天然气有限公司 | C4: =VLOOKUP(B4,公司清单!C:C,1,FALSE) -> 石家庄建投天然气有限公司 | D4: =VLOOKUP(B4,'JV and CTP清单'!C:C,1,FALSE) -> #N/A
A5: MU | B5: 河北赵都天然气有限责任公司 | C5: =VLOOKUP(B5,公司清单!C:C,1,FALSE) -> 河北赵都天然气有限责任公司 | D5: =VLOOKUP(B5,'JV and CTP清单'!C:C,1,FALSE) -> #N/A
A6: MU | B6: 承德市建投天然气有限责任公司 | C6: =VLOOKUP(B6,公司清单!C:C,1,FALSE) -> 承德市建投天然气有限责任公司 | D6: =VLOOKUP(B6,'JV and CTP清单'!C:C,1,FALSE) -> #N/A
A7: MU | B7: 宁晋县建投天然气有限责任公司 | C7: =VLOOKUP(B7,公司清单!C:C,1,FALSE) -> 宁晋县建投天然气有限责任公司 | D7: =VLOOKUP(B7,'JV and CTP清单'!C:C,1,FALSE) -> #N/A
A8: MU | B8: 深州市建投燃气有限公司 | C8: =VLOOKUP(B8,公司清单!C:C,1,FALSE) -> 深州市建投燃气有限公司 | D8: =VLOOKUP(B8,'JV and CTP清单'!C:C,1,FALSE) -> #N/A
A9: MU | B9: 辛集市建投燃气有限公司 | C9: =VLOOKUP(B9,公司清单!C:C,1,FALSE) -> 辛集市建投燃气有限公司 | D9: =VLOOKUP(B9,'JV and CTP清单'!C:C,1,FALSE) -> #N/A
A10: MU | B10: 晋州市建投燃气有限公司 | C10: =VLOOKUP(B10,公司清单!C:C,1,FALSE) -> 晋州市建投燃气有限公司 | D10: =VLOOKUP(B10,'JV and CTP清单'!C:C,1,FALSE) -> #N/A
A11: MU | B11: 中石油京唐液化天然气有限公司 | C11: =VLOOKUP(B11,公司清单!C:C,1,FALSE) -> 中石油京唐液化天然气有限公司 | D11: =VLOOKUP(B11,'JV and CTP清单'!C:C,1,FALSE) -> #N/A
A12: MU | B12: 石家庄冀燃管道工程有限公司 | C12: =VLOOKUP(B12,公司清单!C:C,1,FALSE) -> 石家庄冀燃管道工程有限公司 | D12: =VLOOKUP(B12,'JV and CTP清单'!C:C,1,FALSE) -> #N/A
A13: MU | B13: 邢台冀燃天然气有限公司 | C13: =VLOOKUP(B13,公司清单!C:C,1,FALSE) -> 邢台冀燃天然气有限公司 | D13: =VLOOKUP(B13,'JV and CTP清单'!C:C,1,FALSE) -> #N/A
... A1342: 绿燃 | B1342: 臻新绿源科技(佛山)有限公司 | C1342: =VLOOKUP(B1342,公司清单!C:C,1,FALSE) -> #N/A | D1342: =VLOOKUP(B1342,'JV and CTP清单'!C:C,1,FALSE) -> #N/A

Sheet 对比
B1: 板块 | C1: 数量
B2: 内地公用 | C2: 575
B3: 再生能源 | C3: =11+206+4+419 -> 640
B4: 延伸 | C4: 98
B5: 气源 | C5: 26
B6: 绿燃 | C6: 2
B7: 合计 | C7: =SUM(C2:C6) -> 1341
B8: 来源：各板块提交清单
B10: 与JV对比情况：
B11: 一级JV总数 | C11: 未匹配总数 | D11: 易高 | E11: 中华煤气BVI | F11: 英文 | G11: 未匹配
B12: 850 | C12: 428 | D12: 95 | E12: 95 | F12: 65 | G12: =C12-D12-E12-F12 -> 173
G13: BVI | H13: 24
G14: HK | H14: 77
G15: 其他（72家） | H15: =72-I15 -> 58 | I15: 14

Sheet 72家未匹配
A1: 名称 | B1: Frango Code | C1: Node - Description
A2: 港華能源研究院控股有限公司 | B2: =VLOOKUP(A2,'JV and CTP清单'!C:P,5,FALSE) -> #N/A | C2: =VLOOKUP(A2,'JV and CTP清单'!C:P,13,FALSE) -> #N/A
A3: 安丘航洲新能源科技有限公司 | B3: =VLOOKUP(A3,'JV and CTP清单'!C:P,5,FALSE) -> PGAQJV | C3: =VLOOKUP(A3,'JV and CTP清单'!C:P,13,FALSE) -> Shandong
A4: 巴彦淖尔市耀进燃气有限公司 | B4: =VLOOKUP(A4,'JV and CTP清单'!C:P,5,FALSE) -> BYYJJV | C4: =VLOOKUP(A4,'JV and CTP清单'!C:P,13,FALSE) -> Inner Mongoria
A5: 保源環境投資有限公司 | B5: =VLOOKUP(A5,'JV and CTP清单'!C:P,5,FALSE) -> 0 | C5: =VLOOKUP(A5,'JV and CTP清单'!C:P,13,FALSE) -> Hong Kong
A6: 北京驰波名气通数据服务有限公司 | B6: =VLOOKUP(A6,'JV and CTP清单'!C:P,5,FALSE) -> TBCTJV | C6: =VLOOKUP(A6,'JV and CTP清单'!C:P,13,FALSE) -> Beijing
A7: 亳州皖华燃气有限公司 | B7: =VLOOKUP(A7,'JV and CTP清单'!C:P,5,FALSE) -> N/A | C7: =VLOOKUP(A7,'JV and CTP清单'!C:P,13,FALSE) -> Anhui
A8: 常州道胜科技产业有限公司 | B8: =VLOOKUP(A8,'JV and CTP清单'!C:P,5,FALSE) -> EICDJV | C8: =VLOOKUP(A8,'JV and CTP清单'!C:P,13,FALSE) -> #N/A
A9: 潮盛投资有限公司 | B9: =VLOOKUP(A9,'JV and CTP清单'!C:P,5,FALSE) -> CSIL | C9: =VLOOKUP(A9,'JV and CTP清单'!C:P,13,FALSE) -> Hong Kong
A10: 潮州枫溪港华燃气有限公司 | B10: =VLOOKUP(A10,'JV and CTP清单'!C:P,5,FALSE) -> GDFX | C10: =VLOOKUP(A10,'JV and CTP清单'!C:P,13,FALSE) -> Guangdong
A11: 潮州港华燃气有限公司 | B11: =VLOOKUP(A11,'JV and CTP清单'!C:P,5,FALSE) -> CUJV | C11: =VLOOKUP(A11,'JV and CTP清单'!C:P,13,FALSE) -> Guangdong
A12: 滁州港华综合能源有限公司（合并） | B12: =VLOOKUP(A12,'JV and CTP清单'!C:P,5,FALSE) -> 0 | C12: =VLOOKUP(A12,'JV and CTP清单'!C:P,13,FALSE) -> Anhui | D12: 滁州港华综合能源有限公司
A13: 创熙投资有限公司 | B13: =VLOOKUP(A13,'JV and CTP清单'!C:P,5,FALSE) -> EXCI | C13: =VLOOKUP(A13,'JV and CTP清单'!C:P,13,FALSE) -> BVI
A14: 大连德泰港能投智慧能源有限公司 (Disable) | B14: =VLOOKUP(A14,'JV and CTP清单'!C:P,5,FALSE) -> SEDLJV | C14: =VLOOKUP(A14,'JV and CTP清单'!C:P,13,FALSE) -> Liaoning | D14: 大连德泰港能投智慧能源有限公司
A15: 大连名气通数据服务有限公司 | B15: =VLOOKUP(A15,'JV and CTP清单'!C:P,5,FALSE) -> TTDCJV | C15: =VLOOKUP(A15,'JV and CTP清单'!C:P,13,FALSE) -> Liaoning
A16: 大连屹化新能源科技发展有限公司 | B16: =VLOOKUP(A16,'JV and CTP清单'!C:P,5,FALSE) -> DLTDJV | C16: =VLOOKUP(A16,'JV and CTP清单'!C:P,13,FALSE) -> Liaoning
A17: 丹阳卓惠洗涤有限公司 | B17: =VLOOKUP(A17,'JV and CTP清单'!C:P,5,FALSE) -> CTECDY | C17: =VLOOKUP(A17,'JV and CTP清单'!C:P,13,FALSE) -> #N/A
A18: 得志发展有限公司 | B18: =VLOOKUP(A18,'JV and CTP清单'!C:P,5,FALSE) -> SRDL | C18: =VLOOKUP(A18,'JV and CTP清单'!C:P,13,FALSE) -> Hong Kong
A19: 东莞名气通数据服务有限公司 | B19: =VLOOKUP(A19,'JV and CTP清单'!C:P,5,FALSE) -> TTDGJV | C19: =VLOOKUP(A19,'JV and CTP清单'!C:P,13,FALSE) -> Guangdong
A20: 恩发投资有限公司 | B20: =VLOOKUP(A20,'JV and CTP清单'!C:P,5,FALSE) -> FANI | C20: =VLOOKUP(A20,'JV and CTP清单'!C:P,13,FALSE) -> Hong Kong
A21: 丰城新高焦化有限公司 | B21: =VLOOKUP(A21,'JV and CTP清单'!C:P,5,FALSE) -> FCXCJV | C21: =VLOOKUP(A21,'JV and CTP清单'!C:P,13,FALSE) -> Jiangxi
A22: 港华国际贸易 | B22: =VLOOKUP(A22,'JV and CTP清单'!C:P,5,FALSE) -> NYMY | C22: =VLOOKUP(A22,'JV and CTP清单'!C:P,13,FALSE) -> Mainland China
A23: 港华技术服务（深圳）有限公司 | B23: =VLOOKUP(A23,'JV and CTP清单'!C:P,5,FALSE) -> HPTSZ | C23: =VLOOKUP(A23,'JV and CTP清单'!C:P,13,FALSE) -> Guangdong
A24: 港华能源研究院有限公司 | B24: =VLOOKUP(A24,'JV and CTP清单'!C:P,5,FALSE) -> TGEA | C24: =VLOOKUP(A24,'JV and CTP清单'!C:P,13,FALSE) -> Hong Kong
A25: 港华燃气（枫溪）有限公司 | B25: =VLOOKUP(A25,'JV and CTP清单'!C:P,5,FALSE) -> TCFX | C25: =VLOOKUP(A25,'JV and CTP清单'!C:P,13,FALSE) -> Hong Kong
A26: 港华燃气（融资）有限公司 | B26: =VLOOKUP(A26,'JV and CTP清单'!C:P,5,FALSE) -> TCFL | C26: =VLOOKUP(A26,'JV and CTP清单'!C:P,13,FALSE) -> Hong Kong
... A35: 港华燃气企业有限公司 | B35: =VLOOKUP(A35,'JV and CTP清单'!C:P,5,FALSE) -> N/A | C35: =VLOOKUP(A35,'JV and CTP清单'!C:P,13,FALSE) -> BVI
A36: 港华舒适家（成都）科技服务有限公司 | B36: =VLOOKUP(A36,'JV and CTP清单'!C:P,5,FALSE) -> TCHCD | C36: =VLOOKUP(A36,'JV and CTP清单'!C:P,13,FALSE) -> Sichuan | D36: 港华舒适家成都新都科技服务有限公司
A37: 港华智慧能源（燃气）控股有限公司 | B37: =VLOOKUP(A37,'JV and CTP清单'!C:P,5,FALSE) -> TSHL | C37: =VLOOKUP(A37,'JV and CTP清单'!C:P,13,FALSE) -> Hong Kong
A38: 港华智慧能源（燃气）投资有限公司 | B38: =VLOOKUP(A38,'JV and CTP清单'!C:P,5,FALSE) -> TSIL | C38: =VLOOKUP(A38,'JV and CTP清单'!C:P,13,FALSE) -> Hong Kong
A39: 港华智慧能源有限公司 | B39: =VLOOKUP(A39,'JV and CTP清单'!C:P,5,FALSE) -> TOWN | C39: =VLOOKUP(A39,'JV and CTP清单'!C:P,13,FALSE) -> Cayman Islands
A40: 港华中国电力（香港）综合智慧能源有限公司 | B40: =VLOOKUP(A40,'JV and CTP清单'!C:P,5,FALSE) -> TPIE | C40: =VLOOKUP(A40,'JV and CTP清单'!C:P,13,FALSE) -> Hong Kong
A41: 港华卓明信息（深圳）有限公司 | B41: =VLOOKUP(A41,'JV and CTP清单'!C:P,5,FALSE) -> HFSSZ | C41: =VLOOKUP(A41,'JV and CTP清单'!C:P,13,FALSE) -> Guangdong
A42: 港華紫荊農莊(句容)有限公司 | B42: =VLOOKUP(A42,'JV and CTP清单'!C:P,5,FALSE) -> 0 | C42: =VLOOKUP(A42,'JV and CTP清单'!C:P,13,FALSE) -> Mainland China
A43: 港投分布式能源（融资）有限公司 | B43: =VLOOKUP(A43,'JV and CTP清单'!C:P,5,FALSE) -> HEFL | C43: =VLOOKUP(A43,'JV and CTP清单'!C:P,13,FALSE) -> Hong Kong
A44: 港投分布式能源控股有限公司 | B44: =VLOOKUP(A44,'JV and CTP清单'!C:P,5,FALSE) -> HEHC | C44: =VLOOKUP(A44,'JV and CTP清单'!C:P,13,FALSE) -> Hong Kong
A45: 港投分布式能源投资控股有限公司 | B45: =VLOOKUP(A45,'JV and CTP清单'!C:P,5,FALSE) -> HEIH | C45: =VLOOKUP(A45,'JV and CTP清单'!C:P,13,FALSE) -> BVI
A46: 港投综合电能（融资）有限公司 | B46: =VLOOKUP(A46,'JV and CTP清单'!C:P,5,FALSE) -> HPFL | C46: =VLOOKUP(A46,'JV and CTP清单'!C:P,13,FALSE) -> Hong Kong
A47: 港投综合电能控股有限公司 | B47: =VLOOKUP(A47,'JV and CTP清单'!C:P,5,FALSE) -> HPHC | C47: =VLOOKUP(A47,'JV and CTP清单'!C:P,13,FALSE) -> Hong Kong
A48: 港投综合电能投资控股有限公司 | B48: =VLOOKUP(A48,'JV and CTP清单'!C:P,5,FALSE) -> HPIH | C48: =VLOOKUP(A48,'JV and CTP清单'!C:P,13,FALSE) -> BVI
...
